Workbook
Name bbib105: CornPlantUptake!$E$28
Name bbib12: CornPlantUptake!$E$37
Name bbib120: WheatPlantUptake!$E$7
Name bbib71: CornPlantUptake!$E$31
Name bbib88: CornPlantUptake!$E$44
Name btbl2fna: SoyPlantUptake!$B$23
Name btbl3fnb: CornPlantUptake!$C$75

Sheet Fake Concentrations
A1: Fake concentration of PFAS detected in biosolids | F1: Fake concentration of PFAS in Dairy | M1: ng/kg = ng/L = ppt
A2: Amount | B2: Unit | F2: Amount | G2: Unit
A3: 0.005 | B3: ng/g | F3: 0.005 | G3: ng/g
A5: Fake concentration of PFAS in beef | F5: Fake concentration of PFAS in Corn
A6: Amount | B6: Unit | F6: Amount | G6: Unit
A7: 0.005 | B7: ng/g | F7: 0.005 | G7: ng/g
F9: Fake concentration of PFAS in Wheat
F10: Amount | G10: Unit
F11: 0.005 | G11: ng/g

Sheet BiosolidConc.
A1: Garrett W. Link, Donald M. Reeves, Daniel P. Cassidy, Ethan S. Coffin. Per- and polyfluoroalkyl substances (PFAS) in final treated solids (Biosolids) from 190 Michigan wastewater treatment plants. Journal of Hazardous Materials. Volume 463. 2024. https://doi.org/10.1016/j.jhazmat.2023.132734.
A2: PFAS Detected In Biosolids from 190 Michigan Wastewater Treatment Plants (by dry weight)
B3: DetectionRate (%) | C3: Mean | D3: SE | E3: Max | F3: Unit
A4: Total | C4: 108 | D4: 277 | E4: 3200 | F4: ng/g | G4: ng pfas / g biosolid
A5: PFOS | B5: 95 | C5: 40 | D5: 179 | E5: 2150 | F5: ng/g
A6: PFBA | B6: 15 | C6: 1.1 | D6: 4.1 | E6: 38 | F6: ng/g
A7: PFHxA | B7: 76 | C7: 5.1 | D7: 12 | E7: 162 | F7: ng/g
A8: PFOA | B8: 63 | C8: 4.8 | D8: 11 | E8: 96 | F8: ng/g
A9: PFHxS | B9: 14 | C9: 0.3 | D9: 1.2 | E9: 11 | F9: ng/g
A10: PFPeA | B10: 39 | C10: 3.4 | D10: 11 | E10: 114 | F10: ng/g
A11: PFHpA | B11: 14 | C11: 0.8 | D11: 5.4 | E11: 74 | F11: ng/g
A12: PFNA | B12: 36 | C12: 1.2 | D12: 3.8 | E12: 40 | F12: ng/g
A13: PFDA | B13: 73 | C13: 6.8 | D13: 13 | E13: 120 | F13: ng/g
A14: PFTrDA | B14: 10 | C14: 0.4 | D14: 2.5 | E14: 35 | F14: ng/g
A15: PFBS | B15: 21 | C15: 1.2 | D15: 3.5 | E15: 28 | F15: ng/g
A16: PFPeS | B16: 0.3 | C16: 0 | D16: 0.1 | E16: 1.9 | F16: ng/g
... A28: PFTeDA | B28: 21 | C28: 1 | D28: 11 | E28: 200 | F28: ng/g

Sheet BiosolidAppl
A1: U.S. Environmental Protection Agency, 1994. Biosolids Recycling: Beneficial Technologies for a Better Environment. EPA 832-R-94-009. Washington, D.C. U.S. Environmental Protection Agency, Office of Water.
A2: Biosolids Application Schedules
A3: Type of Site/Vegetation | B3: Schedule | C3: Application Frequency | D3: Application Rate | E3: Application Frequency (per year) | F3: Application Rate (dry tons/acre)
A4: Corn | B4: April, May, after harvest | C4: Annually | D4: 5 to 10 dry tons per acre | E4: 1 | F4: 10
A5: Small Grains | B5: March-June, August, fall | C5: Up to 3 times per year | D5: 2 to 5 dry tons per acre | E5: 3 | F5: 5
A6: Soybean | B6: April-June, fall | C6: Annually | D6: 5 to 20 dry tons per acre | E6: 1 | F6: 20
A7: Hay | B7: After each cutting | C7: Up to 3 times per year | D7: 2 to 5 dry tons per acre | E7: 3 | F7: 5
E9: PFOS Amount (mean) Per Acre/Soil Mass Per Year
E10: Crop | F10: ng pfas/acre | G10: µg pfas/acre | H10: µg pfas/kg soil
E11: Corn | F11: =E4*F4*D16*BiosolidConc.!C5 -> 362873880 | G11: =F11/10^3 -> 362873.88 | H11: =G11/D17/D18 -> 0.2
E12: Small grains (like wheat?) | F12: =E5*F5*D16*BiosolidConc.!C5 -> 544310820 | G12: =F12/10^3 -> 544310.82 | H12: =G12/D17/D18 -> 0.3
E13: Soybean | F13: =E6*F6*D16*BiosolidConc.!C5 -> 725747760 | G13: =F13/10^3 -> 725747.76 | H13: =G13/D17/D18 -> 0.4
B15: Conversions
B16: Tons to Grams | C16: 1 ton = 907184.7 grams | D16: 907184.7
B17: acre-foot of soil to tons | C17: 1 acre-foot = 2000 tons | D17: 2000
B18: Ton to Kg | C18: 1 ton = 907.1847 kg | D18: 907.1847
B19: From: https://efotg.sc.egov.usda.gov/references/Public/NH/Useful_Conversions.pdf

Sheet SoyPlantUptake
A1: Weilan Zhang, Nina Tran, Yanna Liang. Uptake of per- and polyfluoroalkyl substances (PFAS) by soybean across two generations. Journal of Hazardous Materials Advances. Volume 8. 2022. https://doi.org/10.1016/j.hazadv.2022.100170. (https://www.sciencedirect.com/science/article/pii/S2772416622001267)
A2: PFAS in Seed of First Generation Soy Plants - Exposure to a PFAS mixture at 100 µg/kg | G2: Detection Limit is above RfD | H2: ** For nd, the DL is used as a substitute value
B3: Amount | C3: SE +/- | D3: Unit | E3: Detection Limit | F3: DL Unit | G3: Bioaccumulation Factor (BAF = Cplant/Cenviron)
A4: PFBA | B4: 55.66 | C4: 42.06 | D4: µg/kg | E4: 80 | F4: ng/L | G4: =B4/100 -> 0.5566
A5: PFHxA | B5: 12.2 | C5: 11.44 | D5: µg/kg | E5: 40 | F5: ng/L | G5: =B5/100 -> 0.122
A6: PFBS | B6: 3.24 | C6: 2.06 | D6: µg/kg | E6: 10 | F6: ng/L | G6: =B6/100 -> 0.0324
A7: PFHpA | B7: nd | C7: nd | D7: µg/kg | E7: 40 | F7: ng/L | G7: =E7/100 -> 0.4
A8: PFOA | B8: nd | C8: nd | D8: µg/kg | E8: 20 | F8: ng/L | G8: =E8/100 -> 0.2
A9: PFHxS | B9: nd | C9: nd | D9: µg/kg | E9: 5 | F9: ng/L | G9: =E9/100 -> 0.05
A10: PFOS | B10: nd | C10: nd | D10: µg/kg | E10: 10 | F10: ng/L | G10: =E10/100 -> 0.1
A11: GenX | B11: nd | C11: nd | D11: µg/kg | E11: 5 | F11: ng/L | G11: =E11/100 -> 0.05
G15: Soy plant Uptake of PFOS Using BAF*Cenviron | H15: Unit
G16: =G10*BiosolidAppl!H13 -> 0.04 | H16: µg/kg | I16: ug of pfas /kg plant mass
G17: =G16/1000*10^3 -> 0.04 | H17: ng/g | I17: ng of pfas /g of plant mass

Sheet SoyHumanConsumption
A1: Per Capita | F1: Two-Day Average Consumption Commodity Mass (g) per Body Mass (kg) per Day (d) - from WWEIA-FCID 2005-10
H3: Percentiles
D4: N | E4: Percent Consuming | F4: Mean | G4: SE | H4: 0.01 | I4: 0.05 | J4: 0.1 | K4: 0.15 | L4: 0.2 | M4: 0.25 | N4: 0.3 | O4: 0.35 | P4: 0.4 | Q4: 0.45 | R4: 0.5 | S4: 0.55 | T4: 0.6 | U4: 0.65 | V4: 0.7 | W4: 0.75 | X4: 0.8 | Y4: 0.85 | Z4: 0.9 | AA4: 0.95 | AB4: 0.975 | AC4: 0.99 | AD4: Max
A5: Soybean, seed | Soybean, flour | Soybean, flour-babyfood | Soybean, soy milk | Soybean, soy milk-babyfood or infant formula | Soybean, oil | Soybean, oil-babyfood | Soybean, vegetable
A6: Age Range | B6: Gender | C6: Race
A7: All ages | B7: All | C7: All | D7: 24673 | E7: 100 | F7: 0.55 | G7: 0.01 | H7: <0.05 | I7: 0.1 | J7: 0.1 | K7: 0.2 | L7: 0.2 | M7: 0.2 | N7: 0.2 | O7: 0.3 | P7: 0.3 | Q7: 0.3 | R7: 0.3 | S7: 0.4 | T7: 0.4 | U7: 0.4 | V7: 0.5 | W7: 0.6 | X7: 0.6 | Y7: 0.8 | Z7: 1 | AA7: 1.4 | AB7: 2 | AC7: 3.4 | AD7: 108.1†
A8: Birth to < 1 month | B8: All | C8: All | D8: 87 | E8: 75 | F8: 1.57 | G8: 0.42 | H8: 0† | I8: 0† | J8: 0† | K8: 0† | L8: 0† | M8: 0 | N8: 0.3 | O8: 0.6 | P8: 1 | Q8: 1.1 | R8: 1.2 | S8: 1.4 | T8: 1.5 | U8: 1.7 | V8: 1.8 | W8: 1.9 | X8: 2.1† | Y8: 2.3† | Z8: 3.2† | AA8: 8.1† | AB8: 8.1† | AC8: 8.1† | AD8: 8.1†
A9: 1 to < 3 months | B9: All | C9: All | D9: 233 | E9: 74 | F9: 1.29 | G9: 0.12 | H9: 0† | I9: 0† | J9: 0 | K9: 0 | L9: 0 | M9: 0 | N9: 0.2 | O9: 0.7 | P9: 0.9 | Q9: 1 | R9: 1 | S9: 1.2 | T9: 1.3 | U9: 1.4 | V9: 1.6 | W9: 1.7 | X9: 2 | Y9: 2.1 | Z9: 2.9 | AA9: 4.3† | AB9: 5.1† | AC9: 5.1† | AD9: 9.4†
A10: 3 to < 6 months | B10: All | C10: All | D10: 282 | E10: 83 | F10: 1.09 | G10: 0.09 | H10: 0† | I10: 0† | J10: 0 | K10: 0 | L10: 0.1 | M10: 0.3 | N10: 0.6 | O10: 0.7 | P10: 0.7 | Q10: 0.8 | R10: 0.9 | S10: 0.9 | T10: 1.1 | U10: 1.2 | V10: 1.3 | W10: 1.4 | X10: 1.6 | Y10: 1.9 | Z10: 2.7 | AA10: 3.1† | AB10: 4.2† | AC10: 5.0† | AD10: 6.0†
A11: 6 to < 12 months | B11: All | C11: All | D11: 588 | E11: 96 | F11: 1.31 | G11: 0.16 | H11: 0† | I11: <0.05 | J11: 0.1 | K11: 0.2 | L11: 0.4 | M11: 0.5 | N11: 0.6 | O11: 0.6 | P11: 0.7 | Q11: 0.8 | R11: 0.8 | S11: 0.9 | T11: 1 | U11: 1.1 | V11: 1.1 | W11: 1.3 | X11: 1.4 | Y11: 1.8 | Z11: 2.3 | AA11: 3.1 | AB11: 4.2† | AC11: 9.1† | AD11: 52.6†
A12: 1 to < 2 years | B12: All | C12: All | D12: 728 | E12: 100 | F12: 2.59 | G12: 0.73 | H12: 0.1† | I12: 0.2 | J12: 0.3 | K12: 0.4 | L12: 0.4 | M12: 0.5 | N12: 0.6 | O12: 0.6 | P12: 0.7 | Q12: 0.8 | R12: 0.8 | S12: 0.9 | T12: 0.9 | U12: 1 | V12: 1.2 | W12: 1.2 | X12: 1.4 | Y12: 1.6 | Z12: 2 | AA12: 2.7 | AB12: 12.1† | AC12: 74.8† | AD12: 108.1†
A13: 2 to < 3 years | B13: All | C13: All | D13: 751 | E13: 100 | F13: 1.41 | G13: 0.18 | H13: 0.1† | I13: 0.3 | J13: 0.4 | K13: 0.4 | L13: 0.5 | M13: 0.6 | N13: 0.7 | O13: 0.7 | P13: 0.8 | Q13: 0.8 | R13: 0.9 | S13: 1 | T13: 1.1 | U13: 1.2 | V13: 1.2 | W13: 1.3 | X13: 1.4 | Y13: 1.6 | Z13: 1.8 | AA13: 2.2 | AB13: 3.3† | AC13: 17.1† | AD13: 64.5†
A14: 3 to < 6 years | B14: All | C14: All | D14: 1418 | E14: 100 | F14: 1.31 | G14: 0.11 | H14: 0.2† | I14: 0.3 | J14: 0.4 | K14: 0.5 | L14: 0.6 | M14: 0.6 | N14: 0.7 | O14: 0.7 | P14: 0.8 | Q14: 0.9 | R14: 0.9 | S14: 1 | T14: 1 | U14: 1.1 | V14: 1.2 | W14: 1.3 | X14: 1.4 | Y14: 1.5 | Z14: 1.8 | AA14: 2.3 | AB14: 5.4 | AC14: 10.2† | AD14: 59.3†
A15: 6 to < 11 years | B15: All | C15: All | D15: 2292 | E15: 100 | F15: 0.92 | G15: 0.05 | H15: 0.1 | I15: 0.2 | J15: 0.3 | K15: 0.4 | L15: 0.4 | M15: 0.5 | N15: 0.5 | O15: 0.6 | P15: 0.6 | Q15: 0.6 | R15: 0.7 | S15: 0.8 | T15: 0.8 | U15: 0.9 | V15: 0.9 | W15: 1 | X15: 1.1 | Y15: 1.3 | Z15: 1.4 | AA15: 1.7 | AB15: 2.2 | AC15: 5.2 | AD15: 34.2†
A16: 11 to < 16 years | B16: All | C16: All | D16: 2551 | E16: 100 | F16: 0.48 | G16: 0.01 | H16: <0.05 | I16: 0.1 | J16: 0.2 | K16: 0.2 | L16: 0.2 | M16: 0.3 | N16: 0.3 | O16: 0.3 | P16: 0.3 | Q16: 0.4 | R16: 0.4 | S16: 0.4 | T16: 0.5 | U16: 0.5 | V16: 0.5 | W16: 0.6 | X16: 0.7 | Y16: 0.7 | Z16: 0.9 | AA16: 1.1 | AB16: 1.3 | AC16: 1.6 | AD16: 16.5†
A17: 16 to < 21 years | B17: All | C17: All | D17: 2191 | E17: 100 | F17: 0.46 | G17: 0.01 | H17: 0.1 | I17: 0.1 | J17: 0.1 | K17: 0.2 | L17: 0.2 | M17: 0.2 | N17: 0.2 | O17: 0.3 | P17: 0.3 | Q17: 0.3 | R17: 0.4 | S17: 0.4 | T17: 0.4 | U17: 0.5 | V17: 0.5 | W17: 0.6 | X17: 0.6 | Y17: 0.7 | Z17: 0.8 | AA17: 1.1 | AB17: 1.3 | AC17: 1.9 | AD17: 12.5†
A18: 21 to < 30 years | B18: All | C18: All | D18: 2082 | E18: 100 | F18: 0.45 | G18: 0.03 | H18: <0.05 | I18: 0.1 | J18: 0.1 | K18: 0.1 | L18: 0.2 | M18: 0.2 | N18: 0.2 | O18: 0.3 | P18: 0.3 | Q18: 0.3 | R18: 0.3 | S18: 0.3 | T18: 0.4 | U18: 0.4 | V18: 0.5 | W18: 0.5 | X18: 0.6 | Y18: 0.6 | Z18: 0.8 | AA18: 1.1 | AB18: 1.9 | AC18: 3.2 | AD18: 8.1†
A19: 30 to < 40 years | B19: All | C19: All | D19: 2282 | E19: 100 | F19: 0.45 | G19: 0.02 | H19: <0.05 | I19: 0.1 | J19: 0.1 | K19: 0.2 | L19: 0.2 | M19: 0.2 | N19: 0.2 | O19: 0.2 | P19: 0.3 | Q19: 0.3 | R19: 0.3 | S19: 0.3 | T19: 0.4 | U19: 0.4 | V19: 0.4 | W19: 0.5 | X19: 0.5 | Y19: 0.6 | Z19: 0.7 | AA19: 1.1 | AB19: 2 | AC19: 4.5 | AD19: 9.9†
A20: 40 to < 50 years | B20: All | C20: All | D20: 2378 | E20: 100 | F20: 0.4 | G20: 0.01 | H20: <0.05 | I20: 0.1 | J20: 0.1 | K20: 0.1 | L20: 0.2 | M20: 0.2 | N20: 0.2 | O20: 0.2 | P20: 0.3 | Q20: 0.3 | R20: 0.3 | S20: 0.3 | T20: 0.3 | U20: 0.4 | V20: 0.4 | W20: 0.4 | X20: 0.5 | Y20: 0.6 | Z20: 0.7 | AA20: 0.9 | AB20: 1.3 | AC20: 2.2 | AD20: 13.2†
A21: 50 to < 60 years | B21: All | C21: All | D21: 2103 | E21: 100 | F21: 0.41 | G21: 0.02 | H21: <0.05 | I21: 0.1 | J21: 0.1 | K21: 0.1 | L21: 0.2 | M21: 0.2 | N21: 0.2 | O21: 0.2 | P21: 0.2 | Q21: 0.3 | R21: 0.3 | S21: 0.3 | T21: 0.4 | U21: 0.4 | V21: 0.4 | W21: 0.5 | X21: 0.5 | Y21: 0.6 | Z21: 0.7 | AA21: 0.9 | AB21: 1.5 | AC21: 3.1 | AD21: 10.1†
A22: 60 to < 70 years | B22: All | C22: All | D22: 2214 | E22: 100 | F22: 0.37 | G22: 0.02 | H22: <0.05 | I22: 0.1 | J22: 0.1 | K22: 0.1 | L22: 0.2 | M22: 0.2 | N22: 0.2 | O22: 0.2 | P22: 0.2 | Q22: 0.2 | R22: 0.3 | S22: 0.3 | T22: 0.3 | U22: 0.3 | V22: 0.4 | W22: 0.4 | X22: 0.4 | Y22: 0.5 | Z22: 0.6 | AA22: 0.8 | AB22: 1.7 | AC22: 2.6 | AD22: 24.5†
A23: 70 to < 80 years | B23: All | C23: All | D23: 1578 | E23: 100 | F23: 0.35 | G23: 0.02 | H23: <0.05† | I23: 0.1 | J23: 0.1 | K23: 0.1 | L23: 0.1 | M23: 0.2 | N23: 0.2 | O23: 0.2 | P23: 0.2 | Q23: 0.2 | R23: 0.3 | S23: 0.3 | T23: 0.3 | U23: 0.3 | V23: 0.4 | W23: 0.4 | X23: 0.4 | Y23: 0.5 | Z23: 0.5 | AA23: 0.7 | AB23: 1 | AC23: 2.3† | AD23: 14.9†
A24: 80 years and older | B24: All | C24: All | D24: 915 | E24: 100 | F24: 0.36 | G24: 0.02 | H24: <0.05† | I24: 0.1 | J24: 0.1 | K24: 0.1 | L24: 0.2 | M24: 0.2 | N24: 0.2 | O24: 0.2 | P24: 0.2 | Q24: 0.3 | R24: 0.3 | S24: 0.3 | T24: 0.3 | U24: 0.3 | V24: 0.4 | W24: 0.4 | X24: 0.4 | Y24: 0.5 | Z24: 0.6 | AA24: 0.7 | AB24: 1.2 | AC24: 3.2† | AD24: 10.9†
A25: 13 to < 50 years | B25: Female | C25: All | D25: 5543 | E25: 100 | F25: 0.42 | G25: 0.01 | H25: <0.05 | I25: 0.1 | J25: 0.1 | K25: 0.1 | L25: 0.2 | M25: 0.2 | N25: 0.2 | O25: 0.2 | P25: 0.3 | Q25: 0.3 | R25: 0.3 | S25: 0.3 | T25: 0.4 | U25: 0.4 | V25: 0.4 | W25: 0.5 | X25: 0.5 | Y25: 0.6 | Z25: 0.7 | AA25: 1 | AB25: 1.7 | AC25: 2.9 | AD25: 15.7†
A26: All ages | B26: All | C26: Mexican American | D26: 5787 | E26: 100 | F26: 0.52 | G26: 0.02 | H26: <0.05 | I26: 0.1 | J26: 0.1 | K26: 0.1 | L26: 0.2 | M26: 0.2 | N26: 0.2 | O26: 0.2 | P26: 0.3 | Q26: 0.3 | R26: 0.3 | S26: 0.4 | T26: 0.4 | U26: 0.4 | V26: 0.5 | W26: 0.6 | X26: 0.7 | Y26: 0.8 | Z26: 1 | AA26: 1.3 | AB26: 1.7 | AC26: 2.4 | AD26: 81.7†
A27: All ages | B27: All | C27: Non-Hispanic Black | D27: 5337 | E27: 100 | F27: 0.53 | G27: 0.02 | H27: <0.05 | I27: 0.1 | J27: 0.1 | K27: 0.1 | L27: 0.2 | M27: 0.2 | N27: 0.2 | O27: 0.2 | P27: 0.3 | Q27: 0.3 | R27: 0.3 | S27: 0.4 | T27: 0.4 | U27: 0.5 | V27: 0.5 | W27: 0.6 | X27: 0.7 | Y27: 0.8 | Z27: 1 | AA27: 1.5 | AB27: 2 | AC27: 2.9 | AD27: 59.3†
A28: All ages | B28: All | C28: Non-Hispanic White | D28: 10294 | E28: 100 | F28: 0.53 | G28: 0.02 | H28: <0.05 | I28: 0.1 | J28: 0.1 | K28: 0.2 | L28: 0.2 | M28: 0.2 | N28: 0.2 | O28: 0.3 | P28: 0.3 | Q28: 0.3 | R28: 0.3 | S28: 0.4 | T28: 0.4 | U28: 0.4 | V28: 0.5 | W28: 0.5 | X28: 0.6 | Y28: 0.7 | Z28: 0.9 | AA28: 1.3 | AB28: 1.8 | AC28: 3.2 | AD28: 108.1†
A29: All ages | B29: All | C29: Other Hispanic | D29: 2082 | E29: 100 | F29: 0.64 | G29: 0.08 | H29: <0.05 | I29: 0.1 | J29: 0.1 | K29: 0.1 | L29: 0.2 | M29: 0.2 | N29: 0.2 | O29: 0.2 | P29: 0.3 | Q29: 0.3 | R29: 0.3 | S29: 0.4 | T29: 0.4 | U29: 0.5 | V29: 0.5 | W29: 0.6 | X29: 0.7 | Y29: 0.8 | Z29: 1 | AA29: 1.7 | AB29: 2.8 | AC29: 8.1 | AD29: 31.3†
A30: All ages | B30: All | C30: Other Race - Including Multiple | D30: 1173 | E30: 99 | F30: 0.76 | G30: 0.07 | H30: <0.05† | I30: 0.1 | J30: 0.1 | K30: 0.2 | L30: 0.2 | M30: 0.2 | N30: 0.3 | O30: 0.3 | P30: 0.3 | Q30: 0.3 | R30: 0.4 | S30: 0.4 | T30: 0.5 | U30: 0.5 | V30: 0.6 | W30: 0.7 | X30: 0.9 | Y30: 1.1 | Z30: 1.4 | AA30: 2.4 | AB30: 4.5 | AC30: 5.2† | AD30: 98.6†
A32: Notes: '†' indicates estimates are less statistically reliable based on np < 8 * 'Design Effect' guidance published in the Joint Policy on Variance Estimation and Statistical Reporting Standards on NHANES III and CSFII
A34: The “Two-day average” results are based on the average of the two days of food consumption reported in the NHANES/WWEIA survey for those "both day" respondents. If the respondent reports zero consumption on one of the two days and non-zero consumption on the other day, his/her average consumption would be the average of zero and nonzero consumption.
A36: https://fcid.foodrisk.org/dbc/

Sheet Reference Doses
A2: Refence Doses (EPA - IRIS)
B3: Amount | C3: Unit | D3: Source | E3: Webiste
A4: PFOS | B4: 2e-05 | C4: mg/kg/day | D4: EPA | E4: https://www.epa.gov/sites/default/files/2016-05/documents/hesd_pfos_final-plain.pdf
B5: =B4*(10^6) -> 20 | C5: ng/kg/day | D5: EPA | E5: https://www.epa.gov/sites/default/files/2016-05/documents/hesd_pfos_final-plain.pdf
A6: PFBA | B6: 0.001 | C6: mg/kg/day | D6: IRIS | E6: https://iris.epa.gov/ChemicalLanding/&substance_nmbr=701
B7: =B6*(10^6) -> 1000 | C7: ng/kg/day | D7: IRIS | E7: https://iris.epa.gov/ChemicalLanding/&substance_nmbr=701
A8: PFHxA | B8: 0.0005 | C8: mg/kg/day | D8: IRIS | E8: https://iris.epa.gov/ChemicalLanding/&substance_nmbr=704
B9: =B8*(10^6) -> 500 | C9: ng/kg/day | D9: IRIS | E9: https://iris.epa.gov/ChemicalLanding/&substance_nmbr=704
A10: PFOA | B10: 2e-05 | C10: mg/kg/day | D10: EPA | E10: https://www.epa.gov/sites/default/files/2016-05/documents/pfoa_hesd_final-plain.pdf
B11: =B10*(10^6) -> 20 | C11: ng/kg/day | D11: EPA | E11: https://www.epa.gov/sites/default/files/2016-05/documents/pfoa_hesd_final-plain.pdf
A12: PFHxS
A14: PFPeA
A16: PFHpA
A18: PFNA
A20: PFDA
A22: PFUnA
A24: PFDoA
A26: PFTrDA | S26: =48*4 -> 192
S27: =400-S26 -> 208
A28: PFTA
A30: PFBS
A32: PFPeS
A34: PFHpS
A36: PFNS
A38: PFDS
A40: 4:2 FTS
A42: 6:2 FTS
A44: 8:2 FTS
A46: 11ClPF3OUdS
A48: ADONA
A50: 9Cl-PF3ONS
... A66: PFOSA

Sheet Equations
A2: Variable Name | B2: Var Abbrv | E2: PFOS
A3: Average Daily Intake | B3: ADI
A4: Reference Dose | B4: RfD | E4: Beef: | F4: Amount | G4: Unit
A5: Hazard Ratio | B5: HR | E5: ADI= | F5: ='Fake Concentrations'!A7*BeefHumanConsumption!F7 -> 0.00365 | G5: ng/kg-day
A6: Pollutant Concentration | B6: PoC | E6: HR= | F6: =F5/'Reference Doses'!B5 -> 0.0001825 | G6: -
A7: Food Consumption | B7: FC
A9: Equations | E9: Dairy: | F9: Amount | G9: Unit
A10: ADI= | B10: PoC * FC | E10: ADI= | F10: ='Fake Concentrations'!F3*DairyHumanConsumption!D5 -> 0.0335 | G10: ng/kg-day
A11: HR= | B11: ADI/RfD | E11: HR= | F11: =F10/'Reference Doses'!B5 -> 0.001675 | G11: -
E14: Corn: | F14: Amount | G14: Unit
E15: ADI= | F15: =CornHumanConsumption!F7*'Fake Concentrations'!F7 -> 0.007 | G15: ng/kg/day
E16: HR= | F16: =F15/'Reference Doses'!B5 -> 0.00035 | G16: -
E19: Wheat: | F19: Amount | G19: Unit
E20: ADI= | F20: ='Fake Concentrations'!F11*WheatHumanConsumption!F7 -> 0.00785 | G20: ng/kg/day
E21: HR= | F21: =F20/'Reference Doses'!B5 -> 0.0003925 | G21: -
E24: Soy: | F24: Amount | G24: Unit
E25: ADI= | F25: =SoyHumanConsumption!F7*SoyPlantUptake!G17 -> 0.022 | G25: ng/kg/day | H25: ng pfos /kg body mass/day
E26: HR= | F26: =F25/'Reference Doses'!B5 -> 0.0011 | G26: -

Sheet CornPlantUptake
A1: Bei Wen, Yali Wu, Hongna Zhang, Yu Liu, Xiaoyu Hu, Honglin Huang, Shuzhen Zhang. The roles of protein and lipid in the accumulation and distribution of perfluorooctane sulfonate (PFOS) and perfluorooctanoate (PFOA) in plants grown in biosolids-amended soils. Environmental Pollution. Volume 216. 2016. Pages 682-688. https://doi.org/10.1016/j.envpol.2016.06.032.
A2: PFAS in Biosolid Amended Soil (20 tons/hectare/year)
B3: Amount | C3: SE +/- | D3: Unit | E3: Detection Limit | F3: DL Unit
A4: PFOS | B4: 154.4 | C4: 18.6 | D4: ng/g
A5: PFOA | B5: 416.8 | C5: 29.5 | D5: ng/g
A7: PFOS (soil: 154.4 ± 18.6 ng/g)
B8: Croot | C8: SE | D8: Cshoots | E8: SE
A9: Alfalfa | B9: 481.4 | C9: 6.7 | D9: 62.9 | E9: 7.3
A10: Lettuce | B10: 600.8 | C10: 63.4 | D10: 61.2 | E10: 5.3
A11: Maize | B11: 408.9 | C11: 37.7 | D11: 25.5 | E11: 4.4
A12: Mung bean | B12: 640.2 | C12: 41.4 | D12: 105.5 | E12: 8.9
A13: Radish | B13: 403.2 | C13: 56.1 | D13: 72.3 | E13: 17.8
A14: Ryegrass | B14: 212.4 | C14: 29.8 | D14: 27.9 | E14: 3.5
A15: Soybean | B15: 723.6 | C15: 54.9 | D15: 39.9 | E15: 2.8
A16: PFOA (soil: 416.8 ± 29.5 ng/g)
A17: Alfalfa | B17: 4310.3 | C17: 303 | D17: 1311.5 | E17: 201.1
A18: Lettuce | B18: 2523.2 | C18: 251.4 | D18: 493.6 | E18: 42.7
A19: Maize | B19: 703.4 | C19: 38.1 | D19: 85.8 | E19: 2.4
A20: Mung bean | B20: 3230.1 | C20: 292.8 | D20: 3500.9 | E20: 166.3
A21: Radish | B21: 1250.3 | C21: 169.2 | D21: 2227.4 | E21: 54.3
A22: Ryegrass | B22: 977.8 | C22: 88.7 | D22: 550.8 | E22: 59
A23: Soybean | B23: 1335.9 | C23: 100.4 | D23: 123.6 | E23: 11.8
A25: Rossella Ghisi, Teofilo Vamerali, Sergio Manzetti. Accumulation of perfluorinated alkyl substances (PFAS) in agricultural plants: A review. Environmental Research. Volume 169. 2019. Pages 326-341, https://doi.org/10.1016/j.envres.2018.10.023. (https://www.sciencedirect.com/science/article/pii/S0013935118305577)
A26: Table 2. Initial PFAS concentrations (mg/kg soil) and their accumulation in different crop plant parts (μg/kg d.w.).
A27: Plant | B27: Compounds | C27: Treatment and initial soil concentrations (mg/kg soil) | D27: Concentrations in plants (μg/kg d.w.) | E27: References
A28: Maize straw | B28: PFOA, PFOS | C28: Spiked soil. 0–50 for each compound | D28: At 1 mg/kg: | E28: Stahl et al. (2009)
D29: PFOA: 126
D30: PFOS: 104
A31: Maize straw | B31: PFAA mixture, ten compounds | C31: Spiked soil. 0.25 and 1 for each substance | D31: At 1 mg/kg: | E31: Krippner et al. (2015)
D32: PFBA: 35233
D33: PFBS: 1843
D34: PFOA: 645
D35: PFOS: 617
D36: ƩPFASs = 52200
A37: Maize stover | B37: PFAA mixture | C37: Soil + urban 2x biosolids. | D37: PFBA: 4.21 | E37: Blaine et al. (2013)
D38: PFBS: <LOQ
C39: 0.00716, as Ʃ. | D39: PFOA: <LOQ
C40: PFBA: 0.00010 | D40: PFOS: <LOQ
C41: PFBS: 0.00039 | D41: ƩPFASs = 4.49
C42: PFOA: 0.00128
...

Sheet WheatPlantUptake
A1: Rossella Ghisi, Teofilo Vamerali, Sergio Manzetti. Accumulation of perfluorinated alkyl substances (PFAS) in agricultural plants: A review. Environmental Research. Volume 169. 2019. Pages 326-341, https://doi.org/10.1016/j.envres.2018.10.023. (https://www.sciencedirect.com/science/article/pii/S0013935118305577)
A2: Table 2. Initial PFAS concentrations (mg/kg soil) and their accumulation in different crop plant parts (μg/kg d.w.).
A3: Plant | B3: Compounds | C3: Treatment and initial soil concentrations (mg/kg soil) | D3: Concentrations in plants (μg/kg d.w.) | E3: References
A4: Wheat straw | B4: PFOA, PFOS | C4: Spiked soil. 0–50 for each compound | D4: At 1 mg/kg: | E4: Stahl et al. (2009)
D5: PFOA: 1900
D6: PFOS: 270
A7: Wheat straw | B7: PFAA mixture | C7: Soil + biosolids at different rates: 0.0414–0.220, as ƩPFASs. | D7: At 0.220 mg/kg as total amount: | E7: Wen et al. (2014)
D8: PFBA: 22.2
C9: At the highest rate: | D9: PFBS: 21.8
C10: PFBA: 0.0135 | D10: PFOA: 22.1
C11: PFBS: 0.0312 | D11: PFOS: 11.0
C12: PFOA: 0.0261 | D12: ƩPFASs = 178
C13: PFOS: 0.0408
A14: Wheat grains | B14: PFOA, PFOS | C14: Spiked soil. 0–50 for each compound | D14: At 1 mg/kg: | E14: Stahl et al. (2009)
D15: PFOA: 9
D16: PFOS: 0
A17: Wheat grains | B17: PFAA mixture | C17: Soil + biosolids at different rates: 0.0414–0.220, as ƩPFASs. | D17: At 0.220 mg/kg as total amount: | E17: Wen et al. (2014)
D18: PFBA: 6.49
C19: At the highest rate: | D19: PFBS: <MDL
C20: PFBA: 0.0135 | D20: PFOA: 2.90
C21: PFBS: 0.0312 | D21: PFOS: 2.53
C22: PFOA: 0.0261 | D22: ƩPFASs = 35.6
C23: PFOS: 0.0408
A24: Wheat husks | B24: PFAA mixture | C24: Soil + biosolids at different rates: 0.0414–0.220, as ƩPFASs. | D24: At 0.220 mg/kg as total amount: | E24: Wen et al. (2014)
D25: PFBA: 5.77
C26: At the highest rate: | D26: PFBS: <MDL
C27: PFBA: 0.0135 | D27: PFOA: 4.19
C28: PFBS: 0.0312 | D28: PFOS: 2.20
C29: PFOA: 0.0261 | D29: ƩPFASs = 37.8
C30: PFOS: 0.0408
A32: Rossella Ghisi, Teofilo Vamerali, Sergio Manzetti. Accumulation of perfluorinated alkyl substances (PFAS) in agricultural plants: A review. Environmental Research. Volume 169. 2019. Pages 326-341, https://doi.org/10.1016/j.envres.2018.10.023. (https://www.sciencedirect.com/science/article/pii/S0013935118305577)
A33: Table 3. Crop plant part analyzed, initial PFAS concentrations (mg/kg soil), soil organic matter (SOM) or organic carbon (OC) contents and bioconcentration factors (concentration in plant parts/initial concentration in soil).
A34: Plant species and parts | B34: Compounds and initial concentrations (mg/kg) | C34: PFBA, PFBS bioconcentration factors | D34: PFOA, PFOS bioconcentration factors | E34: SOM or OC contents | F34: References
A35: PFOA: 0–50 | C35: Values at 0.25 and 1 mg/Kg: | D35: na | E35: Stahl et al. (2009)
C36: PFOA: 3.20; 1.90
A37: PFOS: 0–50 | C37: PFOS: 0.20; 0.27
A38: Wheat straw | B38: PFAA mixture from the highest biosolid addition: | C38: PFBA: 1.64 | D38: PFOA: 0.847 | E38: SOM: 2.76% | F38: Wen et al. (2014)
C39: PFBS: 0.635 | D39: PFOS: 0.270
B40: PFBA: 0.0135
B41: PFBS: 0.0312
...

Sheet DairyHumanConsumption
A2: From EPA Exposure handbook
A3: Per Capita 2-Day Average Intake of Total Dairy Products Based on 1994−1996, 1998 CSFII (g/kg-day, edible portion, uncooked weight)
B4: N | C4: PC | D4: Mean | E4: SE | F4: 1st | G4: 5th | H4: 10th | I4: 25th | J4: 50th | K4: 75th | L4: 90th | M4: 95th | N4: 99th | O4: Max
A5: Whole population | B5: 20607 | C5: 99.5 | D5: 6.7 | E5: 0.1 | F5: 0.01 | G5: 0.2 | H5: 0.4 | I5: 1.2 | J5: 3.2 | K5: 7.3 | L5: 16.1 | M5: 25.4 | N5: 52.1 | O5: 223
A6: Birth to 1 year | B6: 1486 | C6: 79.5 | D6: 12.6 | E6: 0.9 | F6: 0 | G6: 0 | H6: 0 | I6: 1 | J6: 8 | K6: 14.1 | L6: 24.1 | M6: 48.7 | N6: 127 | O6: 186
A7: 1 to 2 years | B7: 2096 | C7: 99.8 | D7: 36.7 | E7: 0.7 | F7: 0.4 | G7: 3.9 | H7: 7.7 | I7: 17.4 | J7: 31.3 | K7: 49.8 | L7: 72.1 | M7: 88.3 | N7: 126 | O7: 223
A8: 3 to 5 years | B8: 4391 | C8: 100 | D8: 23.3 | E8: 0.3 | F8: 1.1 | G8: 4.2 | H8: 7 | I8: 13 | J8: 20.8 | K8: 30.9 | L8: 42 | M8: 49.4 | N8: 67.7 | O8: 198
A9: 6 to 12 years | B9: 2089 | C9: 100 | D9: 13.6 | E9: 0.4 | F9: 0.3 | G9: 1.8 | H9: 3.5 | I9: 6.7 | J9: 11.7 | K9: 18.5 | L9: 26 | M9: 31.5 | N9: 42.7 | O9: 80.6
A10: 13 to 19 years | B10: 1222 | C10: 99.8 | D10: 5.6 | E10: 0.2 | F10: 0.01 | G10: 0.2 | H10: 0.5 | I10: 1.5 | J10: 4.2 | K10: 8.1 | L10: 12.5 | M10: 15.5 | N10: 25.4 | O10: 32.7
A11: 20 to 49 years | B11: 4677 | C11: 99.8 | D11: 3.3 | E11: 0.1 | F11: 0.01 | G11: 0.2 | H11: 0.3 | I11: 0.9 | J11: 2.2 | K11: 4.6 | L11: 7.6 | M11: 9.9 | N11: 14.9 | O11: 36.4
A12: 50+ years | B12: 4646 | C12: 99.8 | D12: 3.2 | E12: 0.1 | F12: 0.02 | G12: 0.2 | H12: 0.4 | I12: 1 | J12: 2.4 | K12: 4.5 | L12: 6.9 | M12: 8.9 | N12: 14.1 | O12: 42.5
A13: American Indian, Alaska, Native | B13: 177 | C13: 99.8 | D13: 8 | E13: 1.1 | F13: 0 | G13: 0 | H13: 0.1 | I13: 0.8 | J13: 3.1 | K13: 11 | L13: 21.2 | M13: 30.2 | N13: 68.9 | O13: 146.2
A14: Asian, Pacific Islander | B14: 557 | C14: 97 | D14: 6.4 | E14: 0.4 | F14: 0 | G14: 0 | H14: 0 | I14: 0.6 | J14: 3 | K14: 7.4 | L14: 14.9 | M14: 28.1 | N14: 51.7 | O14: 164.8
A15: Black | B15: 2740 | C15: 99.6 | D15: 5.6 | E15: 0.2 | F15: 0 | G15: 0.1 | H15: 0.2 | I15: 0.6 | J15: 2.1 | K15: 6.5 | L15: 14.7 | M15: 23.3 | N15: 45.4 | O15: 185.6
A16: Other | B16: 1638 | C16: 99.1 | D16: 9.5 | E16: 0.6 | F16: 0 | G16: 0.1 | H16: 0.4 | I16: 1.3 | J16: 4.2 | K16: 11.5 | L16: 25.4 | M16: 36.3 | N16: 69.3 | O16: 185.2
A17: White | B17: 15495 | C17: 99.6 | D17: 6.6 | E17: 0.1 | F17: 0 | G17: 0.3 | H17: 0.5 | I17: 1.4 | J17: 3.4 | K17: 7.2 | L17: 15.6 | M17: 24.7 | N17: 51.2 | O17: 223.2

Sheet BeefHumanConsumption
A1: Per Capita | F1: Two-Day Average Consumption Commodity Mass (g) per Body Mass (kg) per Day (d) - from WWEIA-FCID 2005-10
H3: Percentiles
D4: N | E4: Percent Consuming | F4: Mean | G4: SE | H4: 0.01 | I4: 0.05 | J4: 0.1 | K4: 0.15 | L4: 0.2 | M4: 0.25 | N4: 0.3 | O4: 0.35 | P4: 0.4 | Q4: 0.45 | R4: 0.5 | S4: 0.55 | T4: 0.6 | U4: 0.65 | V4: 0.7 | W4: 0.75 | X4: 0.8 | Y4: 0.85 | Z4: 0.9 | AA4: 0.95 | AB4: 0.975 | AC4: 0.99 | AD4: Max
A5: Beef, meat | Beef, meat-babyfood | Beef, meat, dried | Beef, meat byproducts | Beef, meat byproducts-babyfood | Beef, fat | Beef, fat-babyfood | Beef, kidney | Beef, liver | Beef, liver-babyfood
A6: Age Range | B6: Gender | C6: Race
A7: All ages | B7: All | C7: All | D7: 24673 | E7: 86 | F7: 0.73 | G7: 0.01 | H7: 0 | I7: 0 | J7: 0 | K7: <0.05 | L7: <0.05 | M7: <0.05 | N7: 0.1 | O7: 0.2 | P7: 0.3 | Q7: 0.4 | R7: 0.4 | S7: 0.5 | T7: 0.6 | U7: 0.8 | V7: 0.9 | W7: 1 | X7: 1.2 | Y7: 1.5 | Z7: 1.8 | AA7: 2.5 | AB7: 3.2 | AC7: 4.2 | AD7: 20.0†
A8: Birth to < 1 month | B8: All | C8: All | D8: 87 | E8: 0 | F8: 0 | G8: 0 | H8: 0† | I8: 0† | J8: 0† | K8: 0† | L8: 0† | M8: 0 | N8: 0 | O8: 0 | P8: 0 | Q8: 0 | R8: 0 | S8: 0 | T8: 0 | U8: 0 | V8: 0 | W8: 0 | X8: 0† | Y8: 0† | Z8: 0† | AA8: 0† | AB8: 0† | AC8: 0† | AD8: 0†
A9: 1 to < 3 months | B9: All | C9: All | D9: 233 | E9: <0.5 | F9: <0.005 | G9: <0.005 | H9: 0† | I9: 0† | J9: 0 | K9: 0 | L9: 0 | M9: 0 | N9: 0 | O9: 0 | P9: 0 | Q9: 0 | R9: 0 | S9: 0 | T9: 0 | U9: 0 | V9: 0 | W9: 0 | X9: 0 | Y9: 0 | Z9: 0 | AA9: 0† | AB9: 0† | AC9: 0† | AD9: <0.05†
A10: 3 to < 6 months | B10: All | C10: All | D10: 282 | E10: 5 | F10: 0.02 | G10: 0.01 | H10: 0† | I10: 0† | J10: 0 | K10: 0 | L10: 0 | M10: 0 | N10: 0 | O10: 0 | P10: 0 | Q10: 0 | R10: 0 | S10: 0 | T10: 0 | U10: 0 | V10: 0 | W10: 0 | X10: 0 | Y10: 0 | Z10: 0 | AA10: <0.05† | AB10: <0.05† | AC10: 1.0† | AD10: 1.9†
A11: 6 to < 12 months | B11: All | C11: All | D11: 588 | E11: 49 | F11: 0.75 | G11: 0.12 | H11: 0† | I11: 0 | J11: 0 | K11: 0 | L11: 0 | M11: 0 | N11: 0 | O11: 0 | P11: 0 | Q11: 0 | R11: 0 | S11: <0.05 | T11: <0.05 | U11: 0.1 | V11: 0.4 | W11: 0.9 | X11: 1.1 | Y11: 1.7 | Z11: 2.6 | AA11: 4.1 | AB11: 5.2† | AC11: 6.6† | AD11: 12.7†
A12: 1 to < 2 years | B12: All | C12: All | D12: 728 | E12: 81 | F12: 1.27 | G12: 0.09 | H12: 0† | I12: 0 | J12: 0 | K12: 0 | L12: <0.05 | M12: <0.05 | N12: <0.05 | O12: 0.1 | P12: 0.3 | Q12: 0.5 | R12: 0.7 | S12: 0.9 | T12: 1.1 | U12: 1.3 | V12: 1.5 | W12: 1.8 | X12: 2.1 | Y12: 2.7 | Z12: 3.5 | AA12: 4.9 | AB12: 6.6† | AC12: 7.2† | AD12: 20.0†
A13: 2 to < 3 years | B13: All | C13: All | D13: 751 | E13: 88 | F13: 1.46 | G13: 0.08 | H13: 0† | I13: 0 | J13: 0 | K13: <0.05 | L13: <0.05 | M13: 0.1 | N13: 0.3 | O13: 0.5 | P13: 0.7 | Q13: 0.8 | R13: 0.9 | S13: 1.2 | T13: 1.3 | U13: 1.5 | V13: 1.8 | W13: 2.1 | X13: 2.6 | Y13: 3.1 | Z13: 3.7 | AA13: 4.5 | AB13: 6.0† | AC13: 7.7† | AD13: 10.5†
A14: 3 to < 6 years | B14: All | C14: All | D14: 1418 | E14: 89 | F14: 1.35 | G14: 0.09 | H14: 0† | I14: 0 | J14: 0 | K14: <0.05 | L14: <0.05 | M14: 0.1 | N14: 0.2 | O14: 0.4 | P14: 0.6 | Q14: 0.8 | R14: 0.9 | S14: 1 | T14: 1.1 | U14: 1.4 | V14: 1.6 | W14: 1.8 | X14: 2.2 | Y14: 2.5 | Z14: 3.1 | AA14: 4.2 | AB14: 6 | AC14: 9.2† | AD14: 13.7†
A15: 6 to < 11 years | B15: All | C15: All | D15: 2292 | E15: 90 | F15: 1.14 | G15: 0.05 | H15: 0 | I15: 0 | J15: <0.05 | K15: <0.05 | L15: 0.1 | M15: 0.2 | N15: 0.2 | O15: 0.4 | P15: 0.5 | Q15: 0.7 | R15: 0.8 | S15: 1 | T15: 1.1 | U15: 1.3 | V15: 1.5 | W15: 1.7 | X15: 1.9 | Y15: 2.2 | Z15: 2.7 | AA15: 3.6 | AB15: 4.3 | AC15: 5.8 | AD15: 11.9†
A16: 11 to < 16 years | B16: All | C16: All | D16: 2551 | E16: 89 | F16: 0.83 | G16: 0.05 | H16: 0 | I16: 0 | J16: 0 | K16: <0.05 | L16: <0.05 | M16: 0.1 | N16: 0.2 | O16: 0.3 | P16: 0.4 | Q16: 0.4 | R16: 0.5 | S16: 0.6 | T16: 0.7 | U16: 0.8 | V16: 1 | W16: 1.2 | X16: 1.4 | Y16: 1.7 | Z16: 2 | AA16: 2.8 | AB16: 3.4 | AC16: 4.8 | AD16: 13.0†
A17: 16 to < 21 years | B17: All | C17: All | D17: 2191 | E17: 88 | F17: 0.79 | G17: 0.04 | H17: 0 | I17: 0 | J17: 0 | K17: <0.05 | L17: <0.05 | M17: 0.1 | N17: 0.1 | O17: 0.2 | P17: 0.3 | Q17: 0.4 | R17: 0.5 | S17: 0.6 | T17: 0.7 | U17: 0.8 | V17: 1 | W17: 1.2 | X17: 1.4 | Y17: 1.6 | Z17: 2 | AA17: 2.7 | AB17: 3.3 | AC17: 4.2 | AD17: 10.7†
A18: 21 to < 30 years | B18: All | C18: All | D18: 2082 | E18: 86 | F18: 0.69 | G18: 0.03 | H18: 0 | I18: 0 | J18: 0 | K18: <0.05 | L18: <0.05 | M18: 0.1 | N18: 0.1 | O18: 0.2 | P18: 0.3 | Q18: 0.4 | R18: 0.5 | S18: 0.5 | T18: 0.6 | U18: 0.8 | V18: 0.9 | W18: 1 | X18: 1.2 | Y18: 1.4 | Z18: 1.7 | AA18: 2.3 | AB18: 3 | AC18: 3.8 | AD18: 10.4†
A19: 30 to < 40 years | B19: All | C19: All | D19: 2282 | E19: 86 | F19: 0.7 | G19: 0.02 | H19: 0 | I19: 0 | J19: 0 | K19: <0.05 | L19: <0.05 | M19: 0.1 | N19: 0.1 | O19: 0.2 | P19: 0.3 | Q19: 0.4 | R19: 0.4 | S19: 0.5 | T19: 0.6 | U19: 0.7 | V19: 0.9 | W19: 1 | X19: 1.2 | Y19: 1.5 | Z19: 1.8 | AA19: 2.4 | AB19: 2.9 | AC19: 3.7 | AD19: 6.0†
A20: 40 to < 50 years | B20: All | C20: All | D20: 2378 | E20: 86 | F20: 0.65 | G20: 0.02 | H20: 0 | I20: 0 | J20: 0 | K20: <0.05 | L20: <0.05 | M20: <0.05 | N20: 0.1 | O20: 0.2 | P20: 0.3 | Q20: 0.4 | R20: 0.4 | S20: 0.5 | T20: 0.6 | U20: 0.7 | V20: 0.8 | W20: 0.9 | X20: 1.1 | Y20: 1.3 | Z20: 1.6 | AA20: 2.1 | AB20: 2.7 | AC20: 3.4 | AD20: 8.7†
A21: 50 to < 60 years | B21: All | C21: All | D21: 2103 | E21: 86 | F21: 0.59 | G21: 0.02 | H21: 0 | I21: 0 | J21: 0 | K21: <0.05 | L21: <0.05 | M21: <0.05 | N21: 0.1 | O21: 0.1 | P21: 0.2 | Q21: 0.3 | R21: 0.4 | S21: 0.5 | T21: 0.6 | U21: 0.6 | V21: 0.7 | W21: 0.9 | X21: 1.1 | Y21: 1.2 | Z21: 1.5 | AA21: 2 | AB21: 2.4 | AC21: 2.9 | AD21: 4.5†
A22: 60 to < 70 years | B22: All | C22: All | D22: 2214 | E22: 86 | F22: 0.55 | G22: 0.03 | H22: 0 | I22: 0 | J22: 0 | K22: <0.05 | L22: <0.05 | M22: <0.05 | N22: 0.1 | O22: 0.1 | P22: 0.2 | Q22: 0.3 | R22: 0.4 | S22: 0.4 | T22: 0.5 | U22: 0.6 | V22: 0.7 | W22: 0.8 | X22: 1 | Y22: 1.1 | Z22: 1.4 | AA22: 1.9 | AB22: 2.3 | AC22: 2.8 | AD22: 12.0†
A23: 70 to < 80 years | B23: All | C23: All | D23: 1578 | E23: 86 | F23: 0.53 | G23: 0.03 | H23: 0† | I23: 0 | J23: 0 | K23: <0.05 | L23: <0.05 | M23: <0.05 | N23: 0.1 | O23: 0.1 | P23: 0.2 | Q23: 0.3 | R23: 0.4 | S23: 0.4 | T23: 0.5 | U23: 0.6 | V23: 0.7 | W23: 0.8 | X23: 0.9 | Y23: 1.1 | Z23: 1.3 | AA23: 1.7 | AB23: 2.1 | AC23: 2.8† | AD23: 6.6†
A24: 80 years and older | B24: All | C24: All | D24: 915 | E24: 83 | F24: 0.47 | G24: 0.02 | H24: 0† | I24: 0 | J24: 0 | K24: 0 | L24: <0.05 | M24: <0.05 | N24: <0.05 | O24: 0.1 | P24: 0.1 | Q24: 0.2 | R24: 0.2 | S24: 0.3 | T24: 0.4 | U24: 0.5 | V24: 0.6 | W24: 0.7 | X24: 0.8 | Y24: 1 | Z24: 1.3 | AA24: 1.8 | AB24: 2.1 | AC24: 2.5† | AD24: 5.2†
A25: 13 to < 50 years | B25: Female | C25: All | D25: 5543 | E25: 84 | F25: 0.55 | G25: 0.01 | H25: 0 | I25: 0 | J25: 0 | K25: 0 | L25: <0.05 | M25: <0.05 | N25: 0.1 | O25: 0.1 | P25: 0.2 | Q25: 0.3 | R25: 0.3 | S25: 0.4 | T25: 0.5 | U25: 0.6 | V25: 0.7 | W25: 0.8 | X25: 0.9 | Y25: 1.1 | Z25: 1.4 | AA25: 1.9 | AB25: 2.6 | AC25: 3.1 | AD25: 8.8†
A26: All ages | B26: All | C26: Mexican American | D26: 5787 | E26: 84 | F26: 0.82 | G26: 0.03 | H26: 0 | I26: 0 | J26: 0 | K26: 0 | L26: <0.05 | M26: 0.1 | N26: 0.1 | O26: 0.2 | P26: 0.3 | Q26: 0.4 | R26: 0.5 | S26: 0.6 | T26: 0.7 | U26: 0.8 | V26: 1 | W26: 1.2 | X26: 1.4 | Y26: 1.7 | Z26: 2.1 | AA26: 2.8 | AB26: 3.7 | AC26: 4.8 | AD26: 10.7†
A27: All ages | B27: All | C27: Non-Hispanic Black | D27: 5337 | E27: 86 | F27: 0.72 | G27: 0.02 | H27: 0 | I27: 0 | J27: 0 | K27: <0.05 | L27: <0.05 | M27: <0.05 | N27: 0.1 | O27: 0.2 | P27: 0.2 | Q27: 0.3 | R27: 0.4 | S27: 0.5 | T27: 0.6 | U27: 0.7 | V27: 0.8 | W27: 1 | X27: 1.2 | Y27: 1.5 | Z27: 1.8 | AA27: 2.6 | AB27: 3.5 | AC27: 4.4 | AD27: 20.0†
A28: All ages | B28: All | C28: Non-Hispanic White | D28: 10294 | E28: 87 | F28: 0.73 | G28: 0.02 | H28: 0 | I28: 0 | J28: 0 | K28: <0.05 | L28: <0.05 | M28: 0.1 | N28: 0.1 | O28: 0.2 | P28: 0.3 | Q28: 0.4 | R28: 0.5 | S28: 0.5 | T28: 0.6 | U28: 0.8 | V28: 0.9 | W28: 1 | X28: 1.2 | Y28: 1.5 | Z28: 1.8 | AA28: 2.4 | AB28: 3 | AC28: 4 | AD28: 13.7†
A29: All ages | B29: All | C29: Other Hispanic | D29: 2082 | E29: 80 | F29: 0.73 | G29: 0.06 | H29: 0 | I29: 0 | J29: 0 | K29: 0 | L29: 0 | M29: <0.05 | N29: <0.05 | O29: 0.1 | P29: 0.2 | Q29: 0.3 | R29: 0.4 | S29: 0.5 | T29: 0.6 | U29: 0.7 | V29: 0.9 | W29: 1 | X29: 1.2 | Y29: 1.4 | Z29: 1.8 | AA29: 2.6 | AB29: 3.5 | AC29: 5.5 | AD29: 12.0†
A30: All ages | B30: All | C30: Other Race - Including Multiple | D30: 1173 | E30: 81 | F30: 0.68 | G30: 0.04 | H30: 0† | I30: 0 | J30: 0 | K30: 0 | L30: <0.05 | M30: <0.05 | N30: <0.05 | O30: 0.1 | P30: 0.2 | Q30: 0.3 | R30: 0.4 | S30: 0.4 | T30: 0.6 | U30: 0.7 | V30: 0.9 | W30: 1 | X30: 1.2 | Y30: 1.5 | Z30: 1.8 | AA30: 2.5 | AB30: 3.3 | AC30: 4.2† | AD30: 10.0†
A32: Notes: '†' indicates estimates are less statistically reliable based on np < 8 * 'Design Effect' guidance published in the Joint Policy on Variance Estimation and Statistical Reporting Standards on NHANES III and CSFII
A34: The “Two-day average” results are based on the average of the two days of food consumption reported in the NHANES/WWEIA survey for those "both day" respondents. If the respondent reports zero consumption on one of the two days and non-zero consumption on the other day, his/her average consumption would be the average of zero and nonzero consumption.

Sheet CornHumanConsumption
A1: Per Capita | F1: Two-Day Average Consumption Commodity Mass (g) per Body Mass (kg) per Day (d) - from WWEIA-FCID 2005-10
H3: Percentiles
D4: N | E4: Percent Consuming | F4: Mean | G4: SE | H4: 0.01 | I4: 0.05 | J4: 0.1 | K4: 0.15 | L4: 0.2 | M4: 0.25 | N4: 0.3 | O4: 0.35 | P4: 0.4 | Q4: 0.45 | R4: 0.5 | S4: 0.55 | T4: 0.6 | U4: 0.65 | V4: 0.7 | W4: 0.75 | X4: 0.8 | Y4: 0.85 | Z4: 0.9 | AA4: 0.95 | AB4: 0.975 | AC4: 0.99 | AD4: Max
A5: Corn, field, flour | Corn, field, flour-babyfood | Corn, field, meal | Corn, field, meal-babyfood | Corn, field, bran | Corn, field, starch | Corn, field, starch-babyfood | Corn, field, syrup | Corn, field, syrup-babyfood | Corn, field, oil | Corn, field, oil-babyfood | Corn, pop | Corn, sweet | Corn, sweet-babyfood
A6: Age Range | B6: Gender | C6: Race
A7: All ages | B7: All | C7: All | D7: 24673 | E7: 100 | F7: 1.4 | G7: 0.03 | H7: <0.05 | I7: 0.1 | J7: 0.2 | K7: 0.3 | L7: 0.4 | M7: 0.4 | N7: 0.5 | O7: 0.6 | P7: 0.7 | Q7: 0.8 | R7: 1 | S7: 1.1 | T7: 1.2 | U7: 1.4 | V7: 1.6 | W7: 1.9 | X7: 2.1 | Y7: 2.5 | Z7: 3.1 | AA7: 4.1 | AB7: 5.3 | AC7: 7.2 | AD7: 27.9†
A8: Birth to < 1 month | B8: All | C8: All | D8: 87 | E8: 46 | F8: 3.98 | G8: 0.77 | H8: 0† | I8: 0† | J8: 0† | K8: 0† | L8: 0† | M8: 0 | N8: 0 | O8: 0 | P8: 0 | Q8: 0 | R8: 0 | S8: 0.9 | T8: 2.3 | U8: 4.3 | V8: 6.7 | W8: 7.9 | X8: 8.2† | Y8: 11.3† | Z8: 14.0† | AA8: 15.0† | AB8: 17.5† | AC8: 17.5† | AD8: 20.0†
A9: 1 to < 3 months | B9: All | C9: All | D9: 233 | E9: 41 | F9: 3.79 | G9: 0.6 | H9: 0† | I9: 0† | J9: 0 | K9: 0 | L9: 0 | M9: 0 | N9: 0 | O9: 0 | P9: 0 | Q9: 0 | R9: 0 | S9: 0 | T9: 1 | U9: 3.2 | V9: 4.5 | W9: 5.4 | X9: 9.5 | Y9: 11.2 | Z9: 12.5 | AA9: 15.6† | AB9: 20.1† | AC9: 24.1† | AD9: 27.9†
A10: 3 to < 6 months | B10: All | C10: All | D10: 282 | E10: 68 | F10: 3.2 | G10: 0.37 | H10: 0† | I10: 0† | J10: 0 | K10: 0 | L10: 0 | M10: 0 | N10: 0 | O10: <0.05 | P10: 0.2 | Q10: 0.8 | R10: 1.9 | S10: 2.2 | T10: 2.6 | U10: 3.1 | V10: 4 | W10: 4.5 | X10: 6.1 | Y10: 7.9 | Z10: 9.4 | AA10: 11.6† | AB10: 16.5† | AC10: 19.0† | AD10: 20.4†
A11: 6 to < 12 months | B11: All | C11: All | D11: 588 | E11: 95 | F11: 3.44 | G11: 0.24 | H11: 0† | I11: <0.05 | J11: 0.1 | K11: 0.4 | L11: 0.5 | M11: 0.6 | N11: 0.9 | O11: 1.2 | P11: 1.4 | Q11: 1.7 | R11: 2 | S11: 2.5 | T11: 2.9 | U11: 3.7 | V11: 4.4 | W11: 5.4 | X11: 6.2 | Y11: 7.5 | Z11: 9 | AA11: 10.3 | AB11: 13.0† | AC11: 15.5† | AD11: 18.3†
A12: 1 to < 2 years | B12: All | C12: All | D12: 728 | E12: 100 | F12: 2.73 | G12: 0.09 | H12: 0.1† | I12: 0.3 | J12: 0.6 | K12: 0.8 | L12: 1.1 | M12: 1.2 | N12: 1.4 | O12: 1.5 | P12: 1.8 | Q12: 2 | R12: 2.3 | S12: 2.5 | T12: 2.8 | U12: 3 | V12: 3.3 | W12: 3.7 | X12: 4.1 | Y12: 4.5 | Z12: 5.7 | AA12: 7 | AB12: 8.1† | AC12: 9.9† | AD12: 15.3†
A13: 2 to < 3 years | B13: All | C13: All | D13: 751 | E13: 100 | F13: 3.5 | G13: 0.14 | H13: 0.3† | I13: 0.6 | J13: 1 | K13: 1.2 | L13: 1.5 | M13: 1.7 | N13: 2 | O13: 2.1 | P13: 2.4 | Q13: 2.6 | R13: 2.8 | S13: 3.2 | T13: 3.5 | U13: 3.7 | V13: 4.1 | W13: 4.4 | X13: 4.9 | Y13: 5.7 | Z13: 7 | AA13: 8.4 | AB13: 10.2† | AC13: 14.4† | AD13: 25.5†
A14: 3 to < 6 years | B14: All | C14: All | D14: 1418 | E14: 100 | F14: 3.27 | G14: 0.08 | H14: 0.5† | I14: 0.9 | J14: 1.1 | K14: 1.4 | L14: 1.6 | M14: 1.9 | N14: 2 | O14: 2.2 | P14: 2.4 | Q14: 2.6 | R14: 2.9 | S14: 3.1 | T14: 3.3 | U14: 3.6 | V14: 3.8 | W14: 4.2 | X14: 4.7 | Y14: 5.2 | Z14: 5.9 | AA14: 6.9 | AB14: 8.5 | AC14: 10.2† | AD14: 15.6†
A15: 6 to < 11 years | B15: All | C15: All | D15: 2292 | E15: 100 | F15: 2.67 | G15: 0.06 | H15: 0.2 | I15: 0.6 | J15: 0.9 | K15: 1.1 | L15: 1.3 | M15: 1.5 | N15: 1.6 | O15: 1.9 | P15: 2 | Q15: 2.1 | R15: 2.3 | S15: 2.5 | T15: 2.7 | U15: 2.9 | V15: 3.1 | W15: 3.4 | X15: 3.7 | Y15: 4.2 | Z15: 4.8 | AA15: 5.9 | AB15: 7.5 | AC15: 8.7 | AD15: 13.2†
A16: 11 to < 16 years | B16: All | C16: All | D16: 2551 | E16: 100 | F16: 1.71 | G16: 0.04 | H16: 0.1 | I16: 0.3 | J16: 0.4 | K16: 0.6 | L16: 0.8 | M16: 0.9 | N16: 1 | O16: 1.1 | P16: 1.2 | Q16: 1.3 | R16: 1.4 | S16: 1.6 | T16: 1.7 | U16: 1.9 | V16: 2.1 | W16: 2.3 | X16: 2.6 | Y16: 2.9 | Z16: 3.3 | AA16: 4 | AB16: 4.5 | AC16: 5.5 | AD16: 9.0†
A17: 16 to < 21 years | B17: All | C17: All | D17: 2191 | E17: 100 | F17: 1.61 | G17: 0.05 | H17: 0.1 | I17: 0.2 | J17: 0.3 | K17: 0.5 | L17: 0.6 | M17: 0.7 | N17: 0.8 | O17: 0.9 | P17: 1.1 | Q17: 1.2 | R17: 1.3 | S17: 1.4 | T17: 1.6 | U17: 1.7 | V17: 1.9 | W17: 2.1 | X17: 2.4 | Y17: 2.7 | Z17: 3.2 | AA17: 4 | AB17: 4.7 | AC17: 6 | AD17: 15.9†
A18: 21 to < 30 years | B18: All | C18: All | D18: 2082 | E18: 100 | F18: 1.36 | G18: 0.04 | H18: <0.05 | I18: 0.1 | J18: 0.2 | K18: 0.3 | L18: 0.4 | M18: 0.5 | N18: 0.6 | O18: 0.7 | P18: 0.8 | Q18: 0.9 | R18: 1 | S18: 1.2 | T18: 1.3 | U18: 1.4 | V18: 1.6 | W18: 1.8 | X18: 2 | Y18: 2.4 | Z18: 2.9 | AA18: 3.7 | AB18: 4.6 | AC18: 5.9 | AD18: 9.2†
A19: 30 to < 40 years | B19: All | C19: All | D19: 2282 | E19: 100 | F19: 1.16 | G19: 0.03 | H19: <0.05 | I19: 0.1 | J19: 0.2 | K19: 0.3 | L19: 0.3 | M19: 0.4 | N19: 0.5 | O19: 0.6 | P19: 0.7 | Q19: 0.7 | R19: 0.8 | S19: 0.9 | T19: 1.1 | U19: 1.2 | V19: 1.4 | W19: 1.6 | X19: 1.8 | Y19: 2.1 | Z19: 2.6 | AA19: 3.3 | AB19: 3.8 | AC19: 4.9 | AD19: 10.6†
A20: 40 to < 50 years | B20: All | C20: All | D20: 2378 | E20: 100 | F20: 1.08 | G20: 0.04 | H20: <0.05 | I20: 0.1 | J20: 0.2 | K20: 0.2 | L20: 0.3 | M20: 0.4 | N20: 0.4 | O20: 0.5 | P20: 0.6 | Q20: 0.7 | R20: 0.8 | S20: 0.9 | T20: 1 | U20: 1.1 | V20: 1.3 | W20: 1.5 | X20: 1.7 | Y20: 1.9 | Z20: 2.3 | AA20: 3 | AB20: 3.7 | AC20: 5 | AD20: 8.4†
A21: 50 to < 60 years | B21: All | C21: All | D21: 2103 | E21: 100 | F21: 0.87 | G21: 0.03 | H21: <0.05 | I21: 0.1 | J21: 0.2 | K21: 0.2 | L21: 0.3 | M21: 0.3 | N21: 0.4 | O21: 0.4 | P21: 0.5 | Q21: 0.6 | R21: 0.7 | S21: 0.7 | T21: 0.9 | U21: 1 | V21: 1.1 | W21: 1.2 | X21: 1.4 | Y21: 1.6 | Z21: 1.9 | AA21: 2.3 | AB21: 2.8 | AC21: 3.7 | AD21: 7.8†
A22: 60 to < 70 years | B22: All | C22: All | D22: 2214 | E22: 100 | F22: 0.74 | G22: 0.03 | H22: <0.05 | I22: 0.1 | J22: 0.1 | K22: 0.2 | L22: 0.2 | M22: 0.3 | N22: 0.3 | O22: 0.4 | P22: 0.4 | Q22: 0.5 | R22: 0.5 | S22: 0.6 | T22: 0.7 | U22: 0.8 | V22: 0.9 | W22: 1 | X22: 1.1 | Y22: 1.4 | Z22: 1.7 | AA22: 2.1 | AB22: 2.5 | AC22: 3.1 | AD22: 5.8†
A23: 70 to < 80 years | B23: All | C23: All | D23: 1578 | E23: 100 | F23: 0.68 | G23: 0.02 | H23: <0.05† | I23: 0.1 | J23: 0.1 | K23: 0.2 | L23: 0.2 | M23: 0.3 | N23: 0.3 | O23: 0.4 | P23: 0.4 | Q23: 0.5 | R23: 0.5 | S23: 0.6 | T23: 0.7 | U23: 0.7 | V23: 0.8 | W23: 0.9 | X23: 1 | Y23: 1.2 | Z23: 1.4 | AA23: 1.8 | AB23: 2.2 | AC23: 2.8† | AD23: 4.8†
A24: 80 years and older | B24: All | C24: All | D24: 915 | E24: 100 | F24: 0.68 | G24: 0.02 | H24: <0.05† | I24: 0.1 | J24: 0.1 | K24: 0.2 | L24: 0.2 | M24: 0.3 | N24: 0.3 | O24: 0.4 | P24: 0.4 | Q24: 0.5 | R24: 0.5 | S24: 0.6 | T24: 0.6 | U24: 0.7 | V24: 0.8 | W24: 0.9 | X24: 1.1 | Y24: 1.2 | Z24: 1.4 | AA24: 1.7 | AB24: 2 | AC24: 2.5† | AD24: 4.2†
A25: 13 to < 50 years | B25: Female | C25: All | D25: 5543 | E25: 100 | F25: 1.15 | G25: 0.03 | H25: <0.05 | I25: 0.1 | J25: 0.2 | K25: 0.2 | L25: 0.3 | M25: 0.4 | N25: 0.5 | O25: 0.6 | P25: 0.7 | Q25: 0.8 | R25: 0.9 | S25: 1 | T25: 1.1 | U25: 1.2 | V25: 1.4 | W25: 1.6 | X25: 1.8 | Y25: 2.1 | Z25: 2.5 | AA25: 3.2 | AB25: 3.9 | AC25: 4.5 | AD25: 11.3†
A26: All ages | B26: All | C26: Mexican American | D26: 5787 | E26: 99 | F26: 1.92 | G26: 0.04 | H26: <0.05 | I26: 0.2 | J26: 0.4 | K26: 0.5 | L26: 0.7 | M26: 0.8 | N26: 1 | O26: 1.1 | P26: 1.2 | Q26: 1.3 | R26: 1.5 | S26: 1.7 | T26: 1.8 | U26: 2 | V26: 2.2 | W26: 2.5 | X26: 2.8 | Y26: 3.3 | Z26: 3.8 | AA26: 4.9 | AB26: 6.2 | AC26: 8.7 | AD26: 20.4†
A27: All ages | B27: All | C27: Non-Hispanic Black | D27: 5337 | E27: 99 | F27: 1.54 | G27: 0.04 | H27: <0.05 | I27: 0.1 | J27: 0.2 | K27: 0.4 | L27: 0.4 | M27: 0.5 | N27: 0.6 | O27: 0.7 | P27: 0.8 | Q27: 0.9 | R27: 1.1 | S27: 1.2 | T27: 1.4 | U27: 1.5 | V27: 1.8 | W27: 2 | X27: 2.3 | Y27: 2.7 | Z27: 3.3 | AA27: 4.3 | AB27: 5.8 | AC27: 8.1 | AD27: 27.9†
A28: All ages | B28: All | C28: Non-Hispanic White | D28: 10294 | E28: 100 | F28: 1.31 | G28: 0.03 | H28: <0.05 | I28: 0.1 | J28: 0.2 | K28: 0.2 | L28: 0.3 | M28: 0.4 | N28: 0.5 | O28: 0.6 | P28: 0.7 | Q28: 0.8 | R28: 0.9 | S28: 1 | T28: 1.1 | U28: 1.3 | V28: 1.5 | W28: 1.7 | X28: 2 | Y28: 2.4 | Z28: 3 | AA28: 4 | AB28: 5.1 | AC28: 6.6 | AD28: 25.5†
A29: All ages | B29: All | C29: Other Hispanic | D29: 2082 | E29: 99 | F29: 1.44 | G29: 0.07 | H29: <0.05 | I29: 0.1 | J29: 0.2 | K29: 0.3 | L29: 0.3 | M29: 0.4 | N29: 0.5 | O29: 0.6 | P29: 0.7 | Q29: 0.9 | R29: 1 | S29: 1.1 | T29: 1.3 | U29: 1.5 | V29: 1.6 | W29: 1.9 | X29: 2.2 | Y29: 2.5 | Z29: 3.1 | AA29: 4.3 | AB29: 5.8 | AC29: 8.1 | AD29: 20.1†
A30: All ages | B30: All | C30: Other Race - Including Multiple | D30: 1173 | E30: 99 | F30: 1.21 | G30: 0.06 | H30: <0.05† | I30: 0.1 | J30: 0.1 | K30: 0.2 | L30: 0.3 | M30: 0.3 | N30: 0.4 | O30: 0.5 | P30: 0.6 | Q30: 0.7 | R30: 0.8 | S30: 0.9 | T30: 1 | U30: 1.1 | V30: 1.4 | W30: 1.6 | X30: 1.9 | Y30: 2.2 | Z30: 2.8 | AA30: 3.7 | AB30: 4.4 | AC30: 6.9† | AD30: 16.5†
A32: Notes: '†' indicates estimates are less statistically reliable based on np < 8 * 'Design Effect' guidance published in the Joint Policy on Variance Estimation and Statistical Reporting Standards on NHANES III and CSFII
A34: The “Two-day average” results are based on the average of the two days of food consumption reported in the NHANES/WWEIA survey for those "both day" respondents. If the respondent reports zero consumption on one of the two days and non-zero consumption on the other day, his/her average consumption would be the average of zero and nonzero consumption.

Sheet WheatHumanConsumption
A1: Per Capita | F1: Two-Day Average Consumption Commodity Mass (g) per Body Mass (kg) per Day (d) - from WWEIA-FCID 2005-10
H3: Percentiles
D4: N | E4: Percent Consuming | F4: Mean | G4: SE | H4: 0.01 | I4: 0.05 | J4: 0.1 | K4: 0.15 | L4: 0.2 | M4: 0.25 | N4: 0.3 | O4: 0.35 | P4: 0.4 | Q4: 0.45 | R4: 0.5 | S4: 0.55 | T4: 0.6 | U4: 0.65 | V4: 0.7 | W4: 0.75 | X4: 0.8 | Y4: 0.85 | Z4: 0.9 | AA4: 0.95 | AB4: 0.975 | AC4: 0.99 | AD4: Max
A5: Wheat, grain | Wheat, grain-babyfood | Wheat, flour | Wheat, flour-babyfood | Wheat, germ | Wheat, bran
A6: Age Range | B6: Gender | C6: Race
A7: All ages | B7: All | C7: All | D7: 24673 | E7: 99 | F7: 1.57 | G7: 0.02 | H7: 0 | I7: 0.3 | J7: 0.4 | K7: 0.5 | L7: 0.6 | M7: 0.7 | N7: 0.8 | O7: 0.9 | P7: 1 | Q7: 1.1 | R7: 1.2 | S7: 1.3 | T7: 1.4 | U7: 1.6 | V7: 1.7 | W7: 1.9 | X7: 2.2 | Y7: 2.6 | Z7: 3.2 | AA7: 4.3 | AB7: 5.4 | AC7: 6.8 | AD7: 16.2†
A8: Birth to < 1 month | B8: All | C8: All | D8: 87 | E8: 10 | F8: <0.005 | G8: <0.005 | H8: 0† | I8: 0† | J8: 0† | K8: 0† | L8: 0† | M8: 0 | N8: 0 | O8: 0 | P8: 0 | Q8: 0 | R8: 0 | S8: 0 | T8: 0 | U8: 0 | V8: 0 | W8: 0 | X8: 0† | Y8: 0† | Z8: <0.05† | AA8: <0.05† | AB8: 0.1† | AC8: 0.1† | AD8: 0.1†
A9: 1 to < 3 months | B9: All | C9: All | D9: 233 | E9: 6 | F9: <0.005 | G9: <0.005 | H9: 0† | I9: 0† | J9: 0 | K9: 0 | L9: 0 | M9: 0 | N9: 0 | O9: 0 | P9: 0 | Q9: 0 | R9: 0 | S9: 0 | T9: 0 | U9: 0 | V9: 0 | W9: 0 | X9: 0 | Y9: 0 | Z9: 0 | AA9: <0.05† | AB9: <0.05† | AC9: 0.1† | AD9: 0.5†
A10: 3 to < 6 months | B10: All | C10: All | D10: 282 | E10: 30 | F10: 0.12 | G10: 0.03 | H10: 0† | I10: 0† | J10: 0 | K10: 0 | L10: 0 | M10: 0 | N10: 0 | O10: 0 | P10: 0 | Q10: 0 | R10: 0 | S10: 0 | T10: 0 | U10: 0 | V10: 0 | W10: <0.05 | X10: <0.05 | Y10: 0.2 | Z10: 0.3 | AA10: 0.6† | AB10: 0.9† | AC10: 2.5† | AD10: 5.6†
A11: 6 to < 12 months | B11: All | C11: All | D11: 588 | E11: 82 | F11: 1.59 | G11: 0.13 | H11: 0† | I11: 0 | J11: 0 | K11: 0 | L11: <0.05 | M11: 0.2 | N11: 0.3 | O11: 0.4 | P11: 0.6 | Q11: 0.7 | R11: 1 | S11: 1.2 | T11: 1.4 | U11: 1.7 | V11: 1.9 | W11: 2.3 | X11: 2.7 | Y11: 3.3 | Z11: 4 | AA11: 5.3 | AB11: 7.0† | AC11: 9.6† | AD11: 12.7†
A12: 1 to < 2 years | B12: All | C12: All | D12: 728 | E12: 99 | F12: 4 | G12: 0.19 | H12: <0.05† | I12: 0.6 | J12: 1.1 | K12: 1.6 | L12: 1.9 | M12: 2.2 | N12: 2.5 | O12: 2.8 | P12: 3 | Q12: 3.2 | R12: 3.5 | S12: 3.8 | T12: 4.2 | U12: 4.5 | V12: 4.8 | W12: 5.3 | X12: 5.8 | Y12: 6.4 | Z12: 7.3 | AA12: 8.8 | AB12: 10.3† | AC12: 12.3† | AD12: 15.7†
A13: 2 to < 3 years | B13: All | C13: All | D13: 751 | E13: 100 | F13: 4.08 | G13: 0.11 | H13: 0.2† | I13: 1.1 | J13: 1.5 | K13: 1.8 | L13: 2.1 | M13: 2.5 | N13: 2.7 | O13: 2.9 | P13: 3.1 | Q13: 3.5 | R13: 3.7 | S13: 4 | T13: 4.3 | U13: 4.6 | V13: 4.9 | W13: 5.3 | X13: 5.9 | Y13: 6.4 | Z13: 7.1 | AA13: 8.5 | AB13: 9.8† | AC13: 10.6† | AD13: 16.2†
A14: 3 to < 6 years | B14: All | C14: All | D14: 1418 | E14: 100 | F14: 4.03 | G14: 0.07 | H14: 0.5† | I14: 1.4 | J14: 1.8 | K14: 2.1 | L14: 2.4 | M14: 2.7 | N14: 2.8 | O14: 3 | P14: 3.2 | Q14: 3.4 | R14: 3.7 | S14: 3.9 | T14: 4.3 | U14: 4.5 | V14: 4.8 | W14: 5.2 | X14: 5.5 | Y14: 6.1 | Z14: 6.7 | AA14: 7.8 | AB14: 8.9 | AC14: 10.0† | AD14: 13.5†
A15: 6 to < 11 years | B15: All | C15: All | D15: 2292 | E15: 100 | F15: 3.2 | G15: 0.06 | H15: 0.5 | I15: 0.9 | J15: 1.3 | K15: 1.6 | L15: 1.8 | M15: 2 | N15: 2.1 | O15: 2.3 | P15: 2.5 | Q15: 2.7 | R15: 2.9 | S15: 3.2 | T15: 3.4 | U15: 3.6 | V15: 3.8 | W15: 4.1 | X15: 4.4 | Y15: 4.8 | Z15: 5.4 | AA15: 6.5 | AB15: 7.2 | AC15: 8.2 | AD15: 12.3†
A16: 11 to < 16 years | B16: All | C16: All | D16: 2551 | E16: 100 | F16: 1.97 | G16: 0.05 | H16: 0.2 | I16: 0.5 | J16: 0.7 | K16: 0.8 | L16: 1 | M16: 1.1 | N16: 1.2 | O16: 1.4 | P16: 1.5 | Q16: 1.6 | R16: 1.7 | S16: 1.8 | T16: 2 | U16: 2.2 | V16: 2.4 | W16: 2.6 | X16: 2.8 | Y16: 3.2 | Z16: 3.5 | AA16: 4.2 | AB16: 4.9 | AC16: 5.7 | AD16: 9.8†
A17: 16 to < 21 years | B17: All | C17: All | D17: 2191 | E17: 100 | F17: 1.61 | G17: 0.04 | H17: 0.1 | I17: 0.4 | J17: 0.5 | K17: 0.7 | L17: 0.8 | M17: 0.9 | N17: 1 | O17: 1.1 | P17: 1.2 | Q17: 1.3 | R17: 1.4 | S17: 1.5 | T17: 1.6 | U17: 1.7 | V17: 1.9 | W17: 2.1 | X17: 2.3 | Y17: 2.6 | Z17: 2.9 | AA17: 3.8 | AB17: 4.2 | AC17: 5.1 | AD17: 8.8†
A18: 21 to < 30 years | B18: All | C18: All | D18: 2082 | E18: 99 | F18: 1.33 | G18: 0.02 | H18: <0.05 | I18: 0.3 | J18: 0.4 | K18: 0.5 | L18: 0.6 | M18: 0.7 | N18: 0.8 | O18: 0.9 | P18: 1 | Q18: 1.1 | R18: 1.2 | S18: 1.3 | T18: 1.4 | U18: 1.5 | V18: 1.6 | W18: 1.7 | X18: 1.9 | Y18: 2.1 | Z18: 2.5 | AA18: 3 | AB18: 3.4 | AC18: 4.1 | AD18: 6.6†
A19: 30 to < 40 years | B19: All | C19: All | D19: 2282 | E19: 100 | F19: 1.25 | G19: 0.02 | H19: <0.05 | I19: 0.3 | J19: 0.4 | K19: 0.5 | L19: 0.6 | M19: 0.7 | N19: 0.8 | O19: 0.8 | P19: 0.9 | Q19: 1 | R19: 1.1 | S19: 1.2 | T19: 1.3 | U19: 1.4 | V19: 1.5 | W19: 1.6 | X19: 1.8 | Y19: 2 | Z19: 2.3 | AA19: 2.9 | AB19: 3.5 | AC19: 4.4 | AD19: 9.6†
A20: 40 to < 50 years | B20: All | C20: All | D20: 2378 | E20: 100 | F20: 1.13 | G20: 0.03 | H20: <0.05 | I20: 0.3 | J20: 0.4 | K20: 0.5 | L20: 0.6 | M20: 0.6 | N20: 0.7 | O20: 0.8 | P20: 0.8 | Q20: 0.9 | R20: 1 | S20: 1.1 | T20: 1.2 | U20: 1.2 | V20: 1.4 | W20: 1.5 | X20: 1.6 | Y20: 1.8 | Z20: 2 | AA20: 2.4 | AB20: 2.9 | AC20: 3.9 | AD20: 6.0†
A21: 50 to < 60 years | B21: All | C21: All | D21: 2103 | E21: 100 | F21: 1.08 | G21: 0.03 | H21: <0.05 | I21: 0.2 | J21: 0.4 | K21: 0.5 | L21: 0.5 | M21: 0.6 | N21: 0.7 | O21: 0.7 | P21: 0.8 | Q21: 0.9 | R21: 0.9 | S21: 1 | T21: 1.1 | U21: 1.2 | V21: 1.3 | W21: 1.4 | X21: 1.5 | Y21: 1.7 | Z21: 1.9 | AA21: 2.3 | AB21: 2.7 | AC21: 3.3 | AD21: 6.2†
A22: 60 to < 70 years | B22: All | C22: All | D22: 2214 | E22: 100 | F22: 1 | G22: 0.02 | H22: 0.1 | I22: 0.3 | J22: 0.4 | K22: 0.5 | L22: 0.5 | M22: 0.6 | N22: 0.7 | O22: 0.7 | P22: 0.8 | Q22: 0.9 | R22: 0.9 | S22: 1 | T22: 1 | U22: 1.1 | V22: 1.2 | W22: 1.3 | X22: 1.4 | Y22: 1.5 | Z22: 1.8 | AA22: 2.1 | AB22: 2.4 | AC22: 2.8 | AD22: 4.9†
A23: 70 to < 80 years | B23: All | C23: All | D23: 1578 | E23: 100 | F23: 1.04 | G23: 0.02 | H23: 0.1† | I23: 0.3 | J23: 0.4 | K23: 0.5 | L23: 0.6 | M23: 0.6 | N23: 0.7 | O23: 0.8 | P23: 0.8 | Q23: 0.9 | R23: 1 | S23: 1 | T23: 1.1 | U23: 1.2 | V23: 1.2 | W23: 1.3 | X23: 1.5 | Y23: 1.6 | Z23: 1.8 | AA23: 2.1 | AB23: 2.3 | AC23: 2.9† | AD23: 4.2†
A24: 80 years and older | B24: All | C24: All | D24: 915 | E24: 100 | F24: 1.06 | G24: 0.02 | H24: 0.2† | I24: 0.3 | J24: 0.4 | K24: 0.5 | L24: 0.6 | M24: 0.6 | N24: 0.7 | O24: 0.8 | P24: 0.8 | Q24: 0.9 | R24: 1 | S24: 1 | T24: 1.1 | U24: 1.2 | V24: 1.3 | W24: 1.3 | X24: 1.5 | Y24: 1.6 | Z24: 1.8 | AA24: 2.1 | AB24: 2.5 | AC24: 3.1† | AD24: 3.8†
A25: 13 to < 50 years | B25: Female | C25: All | D25: 5543 | E25: 100 | F25: 1.23 | G25: 0.02 | H25: <0.05 | I25: 0.3 | J25: 0.4 | K25: 0.5 | L25: 0.6 | M25: 0.7 | N25: 0.7 | O25: 0.8 | P25: 0.9 | Q25: 1 | R25: 1.1 | S25: 1.2 | T25: 1.2 | U25: 1.3 | V25: 1.5 | W25: 1.6 | X25: 1.8 | Y25: 2 | Z25: 2.3 | AA25: 2.8 | AB25: 3.3 | AC25: 3.9 | AD25: 7.0†
A26: All ages | B26: All | C26: Mexican American | D26: 5787 | E26: 98 | F26: 1.57 | G26: 0.03 | H26: 0 | I26: 0.1 | J26: 0.3 | K26: 0.4 | L26: 0.6 | M26: 0.7 | N26: 0.8 | O26: 0.8 | P26: 0.9 | Q26: 1 | R26: 1.2 | S26: 1.3 | T26: 1.5 | U26: 1.6 | V26: 1.8 | W26: 2 | X26: 2.4 | Y26: 2.7 | Z26: 3.4 | AA26: 4.4 | AB26: 5.3 | AC26: 6.6 | AD26: 13.5†
A27: All ages | B27: All | C27: Non-Hispanic Black | D27: 5337 | E27: 99 | F27: 1.44 | G27: 0.03 | H27: 0 | I27: 0.2 | J27: 0.3 | K27: 0.4 | L27: 0.5 | M27: 0.6 | N27: 0.7 | O27: 0.8 | P27: 0.9 | Q27: 0.9 | R27: 1 | S27: 1.1 | T27: 1.3 | U27: 1.4 | V27: 1.6 | W27: 1.8 | X27: 2.1 | Y27: 2.5 | Z27: 3.1 | AA27: 4.2 | AB27: 5.4 | AC27: 6.6 | AD27: 16.2†
A28: All ages | B28: All | C28: Non-Hispanic White | D28: 10294 | E28: 99 | F28: 1.6 | G28: 0.02 | H28: <0.05 | I28: 0.3 | J28: 0.5 | K28: 0.6 | L28: 0.7 | M28: 0.8 | N28: 0.9 | O28: 0.9 | P28: 1 | Q28: 1.1 | R28: 1.2 | S28: 1.3 | T28: 1.4 | U28: 1.6 | V28: 1.7 | W28: 1.9 | X28: 2.2 | Y28: 2.6 | Z28: 3.2 | AA28: 4.3 | AB28: 5.4 | AC28: 6.9 | AD28: 15.7†
A29: All ages | B29: All | C29: Other Hispanic | D29: 2082 | E29: 98 | F29: 1.52 | G29: 0.06 | H29: 0 | I29: 0.1 | J29: 0.3 | K29: 0.4 | L29: 0.5 | M29: 0.6 | N29: 0.7 | O29: 0.8 | P29: 0.9 | Q29: 1 | R29: 1.1 | S29: 1.2 | T29: 1.4 | U29: 1.5 | V29: 1.7 | W29: 1.9 | X29: 2.1 | Y29: 2.5 | Z29: 3.2 | AA29: 4.4 | AB29: 5.7 | AC29: 7.1 | AD29: 11.7†
A30: All ages | B30: All | C30: Other Race - Including Multiple | D30: 1173 | E30: 99 | F30: 1.56 | G30: 0.07 | H30: 0† | I30: 0.2 | J30: 0.3 | K30: 0.5 | L30: 0.6 | M30: 0.7 | N30: 0.8 | O30: 0.9 | P30: 1 | Q30: 1.1 | R30: 1.2 | S30: 1.3 | T30: 1.4 | U30: 1.5 | V30: 1.7 | W30: 1.9 | X30: 2.2 | Y30: 2.7 | Z30: 3.3 | AA30: 4.7 | AB30: 5.6 | AC30: 7.0† | AD30: 11.9†
A32: Notes: '†' indicates estimates are less statistically reliable based on np < 8 * 'Design Effect' guidance published in the Joint Policy on Variance Estimation and Statistical Reporting Standards on NHANES III and CSFII
A34: The “Two-day average” results are based on the average of the two days of food consumption reported in the NHANES/WWEIA survey for those "both day" respondents. If the respondent reports zero consumption on one of the two days and non-zero consumption on the other day, his/her average consumption would be the average of zero and nonzero consumption.

Sheet Human Weight
A2: Mean and Percentile Body Weights (kg) Derived From NHANES (1999−2006) Males and Females Combined
A4: Age Group | B4: N | C4: Mean | D4: 5th | E4: 10th | F4: 15th | G4: 25th | H4: 50th | I4: 75th | J4: 80th | K4: 90th | L4: 95th
A5: Birth to <1 month | B5: 158 | C5: 4.8 | D5: 3.6 | E5: 3.9 | F5: 4.1 | G5: 4.2 | H5: 4.8 | I5: 5.1 | J5: 5.5 | K5: 5.8 | L5: 6.2
A6: 1 to <3 months | B6: 284 | C6: 5.9 | D6: 4.5 | E6: 4.7 | F6: 4.9 | G6: 5.2 | H6: 5.9 | I6: 6.6 | J6: 6.9 | K6: 7.1 | L6: 7.3
A7: 3 to <6 months | B7: 489 | C7: 7.4 | D7: 5.7 | E7: 6.1 | F7: 6.3 | G7: 6.7 | H7: 7.3 | I7: 8 | J7: 8.4 | K7: 8.7 | L7: 9.1
A8: 6 to <12 months | B8: 927 | C8: 9.2 | D8: 7.1 | E8: 7.5 | F8: 7.9 | G8: 8.3 | H8: 9.1 | I8: 10.1 | J8: 10.5 | K8: 10.8 | L8: 11.3
A9: 1 to <2 years | B9: 1176 | C9: 11.4 | D9: 8.9 | E9: 9.3 | F9: 9.7 | G9: 10.3 | H9: 11.3 | I9: 12.4 | J9: 13 | K9: 13.4 | L9: 14
A10: 2 to <3 years | B10: 1144 | C10: 13.8 | D10: 10.9 | E10: 11.5 | F10: 11.9 | G10: 12.4 | H10: 13.6 | I10: 14.9 | J10: 15.8 | K10: 16.3 | L10: 17.1
A11: 3 to <6 years | B11: 2318 | C11: 18.6 | D11: 13.5 | E11: 14.4 | F11: 14.9 | G11: 15.8 | H11: 17.8 | I11: 20.3 | J11: 22 | K11: 23.6 | L11: 26.2
A12: 6 to <11 years | B12: 3593 | C12: 31.8 | D12: 19.7 | E12: 21.3 | F12: 22.3 | G12: 24.4 | H12: 29.3 | I12: 36.8 | J12: 42.1 | K12: 45.6 | L12: 52.5
A13: 11 to <16 years | B13: 5297 | C13: 56.8 | D13: 34 | E13: 37.2 | F13: 40.6 | G13: 45 | H13: 54.2 | I13: 65 | J13: 73 | K13: 79.3 | L13: 88.8
A14: 16 to <21 years | B14: 4851 | C14: 71.6 | D14: 48.2 | E14: 52 | F14: 54.5 | G14: 58.4 | H14: 67.6 | I14: 80.6 | J14: 90.8 | K14: 97.7 | L14: 108
A15: 21 to <30 years | B15: 3232 | C15: 78.4 | D15: 50.8 | E15: 54.7 | F15: 57.9 | G15: 63.3 | H15: 75.2 | I15: 88.2 | J15: 98.5 | K15: 106 | L15: 118
A16: 30 to <40 years | B16: 3176 | C16: 80.8 | D16: 53.5 | E16: 57.4 | F16: 60.1 | G16: 66.1 | H16: 77.9 | I16: 92.4 | J16: 101 | K16: 107 | L16: 118
... A21: Over 80 years | B21: 1430 | C21: 68.5 | D21: 46.9 | E21: 51.4 | F21: 53.8 | G21: 58.2 | H21: 67.4 | I21: 77.4 | J21: 82.6 | K21: 87.2 | L21: 93.6
